<?xml version="1.0"?>
<sdf version="1.6">
  <model name="simple_diff_bot" canonical_link='chassis'>
    <link name="chassis">
      <pose>0 0 0.1 0 0 0</pose>
      <inertial>
        <mass>5.0</mass>
        <inertia>
          <ixx>1</ixx>
          <iyy>1</iyy>
          <izz>1</izz>
        </inertia>
      </inertial>
      <collision name="collision">
        <geometry>
          <box>
            <size>0.5 0.3 0.2</size>
          </box>
        </geometry>
      </collision>
      <visual name="visual">
        <geometry>
          <box>
            <size>0.5 0.3 0.2</size>
          </box>
        </geometry>
        <material>
          <ambient>0 0 1 1</ambient>
          <diffuse>0 0 1 1</diffuse>
        </material>
      </visual>
      <sensor name="lidar" type="gpu_ray">
        <!-- Place lidar on top of the chassis -->
        <pose>0 0 0.15 0 0 0</pose>
        <update_rate>10</update_rate>
        <ray>
          <scan>
            <horizontal>
              <samples>360</samples>
              <resolution>1</resolution>

              <min_angle>-3.14159</min_angle>
              <max_angle>3.14159</max_angle>
            </horizontal>
          </scan>
          <range>
            <min>0.1</min>
            <max>10.0</max>
          </range>
        </ray>
      </sensor>
    </link>

    <!--Left wheel-->
    <link name='left_wheel'>
        <pose relative_to="chassis">-0.5 0.6 0 -1.5707 0 0</pose> <!--angles are in radian-->
        <inertial>
            <mass>1</mass>
            <inertia>
                <ixx>0.043333</ixx>
                <ixy>0</ixy>
                <ixz>0</ixz>
                <iyy>0.043333</iyy>
                <iyz>0</iyz>
                <izz>0.08</izz>
            </inertia>
        </inertial>
        <visual name='visual'>
            <geometry>
                <cylinder>
                    <radius>0.4</radius>
                    <length>0.2</length>
                </cylinder>
            </geometry>
            <material>
                <ambient>1.0 0.0 0.0 1</ambient>
                <diffuse>1.0 0.0 0.0 1</diffuse>
                <specular>1.0 0.0 0.0 1</specular>
            </material>
        </visual>
        <collision name='collision'>
            <geometry>
                <cylinder>
                    <radius>0.4</radius>
                    <length>0.2</length>
                </cylinder>
            </geometry>
        </collision>
    </link>

    <!--The same as left wheel but with different position-->
    <link name='right_wheel'>
        <pose relative_to="chassis">-0.5 -0.6 0 -1.5707 0 0</pose> <!--angles are in radian-->
        <inertial>
            <mass>1</mass>
            <inertia>
                <ixx>0.043333</ixx>
                <ixy>0</ixy>
                <ixz>0</ixz>
                <iyy>0.043333</iyy>
                <iyz>0</iyz>
                <izz>0.08</izz>
            </inertia>
        </inertial>
        <visual name='visual'>
            <geometry>
                <cylinder>
                    <radius>0.4</radius>
                    <length>0.2</length>
                </cylinder>
            </geometry>
            <material>
                <ambient>1.0 0.0 0.0 1</ambient>
                <diffuse>1.0 0.0 0.0 1</diffuse>
                <specular>1.0 0.0 0.0 1</specular>
            </material>
        </visual>
        <collision name='collision'>
            <geometry>
                <cylinder>
                    <radius>0.4</radius>
                    <length>0.2</length>
                </cylinder>
            </geometry>
        </collision>
    </link>
    <!--arbitrary frame-->
    <frame name="caster_frame" attached_to='chassis'>
        <pose>0.8 0 -0.2 0 0 0</pose>
    </frame>

    <!--caster wheel-->
    <link name='caster'>
        <pose relative_to='caster_frame'/>
        <inertial>
            <mass>1</mass>
            <inertia>
                <ixx>0.016</ixx>
                <ixy>0</ixy>
                <ixz>0</ixz>
                <iyy>0.016</iyy>
                <iyz>0</iyz>
                <izz>0.016</izz>
            </inertia>
        </inertial>
        <visual name='visual'>
            <geometry>
                <sphere>
                    <radius>0.2</radius>
                </sphere>
            </geometry>
            <material>
                <ambient>0.0 1 0.0 1</ambient>
                <diffuse>0.0 1 0.0 1</diffuse>
                <specular>0.0 1 0.0 1</specular>
            </material>
        </visual>
        <collision name='collision'>
            <geometry>
                <sphere>
                    <radius>0.2</radius>
                </sphere>
            </geometry>
        </collision>
    </link>

     <!--left wheel joint-->
    <joint name='left_wheel_joint' type='revolute'>
        <pose relative_to='left_wheel'/>
        <parent>chassis</parent>
        <child>left_wheel</child>
        <axis>
            <xyz expressed_in='__model__'>0 1 0</xyz> <!--can be descired to any frame or even arbitrary frames-->
            <limit>
                <lower>-1.79769e+308</lower>    <!--negative infinity-->
                <upper>1.79769e+308</upper>     <!--positive infinity-->
            </limit>
        </axis>
    </joint>

    <!--right wheel joint-->
    <joint name='right_wheel_joint' type='revolute'>
        <pose relative_to='right_wheel'/>
        <parent>chassis</parent>
        <child>right_wheel</child>
        <axis>
            <xyz expressed_in='__model__'>0 1 0</xyz>
            <limit>
                <lower>-1.79769e+308</lower>    <!--negative infinity-->
                <upper>1.79769e+308</upper>     <!--positive infinity-->
            </limit>
        </axis>
    </joint>

    <!--caster wheel joint--> <!--pose defult value is the child-->
    <joint name='caster_wheel' type='ball'>
        <parent>chassis</parent>
        <child>caster</child>
    </joint>

    <plugin name="diff_drive" filename="libignition-gazebo-diff-drive-system.so">
      <left_joint>left_wheel_joint</left_joint>
      <right_joint>right_wheel_joint</right_joint>
      <wheel_separation>0.3</wheel_separation>
      <wheel_radius>0.1</wheel_radius>
      <odom_publish_frequency>30</odom_publish_frequency>
      <topic>cmd_vel</topic>
    </plugin>
  </model>
</sdf>
